Workbook

Sheet 채집 확률표
A1: 장소 | B1: 아이템 | C1: 종류 | D1: 가중치 | E1: 한 번 뽑을 때 확률 | F1: 한 번에 나오는 개수
A2: 크레이터 평원 | B2: 운석 파편 | C2: 기본 재료 | D2: 40 | E2: =D2/SUM($D$2:$D$13) -> 0.2919708 | F2: 1~2개
A3: 크레이터 평원 | B3: 성운 이끼 | C3: 기본 재료 | D3: 20 | E3: =D3/SUM($D$2:$D$13) -> 0.1459854 | F3: 1~2개
A4: 크레이터 평원 | B4: 은하 결정 | C4: 기본 재료 | D4: 15 | E4: =D4/SUM($D$2:$D$13) -> 0.10948905 | F4: 1개
A5: 크레이터 평원 | B5: 별감자 씨앗 | C5: 씨앗 | D5: 10 | E5: =D5/SUM($D$2:$D$13) -> 0.072992701 | F5: 1개
A6: 크레이터 평원 | B6: 네온베리 씨앗 | C6: 씨앗 | D6: 8 | E6: =D6/SUM($D$2:$D$13) -> 0.058394161 | F6: 1개
A7: 크레이터 평원 | B7: 월광호박 씨앗 | C7: 씨앗 | D7: 3 | E7: =D7/SUM($D$2:$D$13) -> 0.02189781 | F7: 1개
A8: 크레이터 평원 | B8: 암흑물질 조각 | C8: 기본 재료 | D8: 4 | E8: =D8/SUM($D$2:$D$13) -> 0.02919708 | F8: 1개
A9: 크레이터 평원 | B9: 철운석 덩어리 | C9: 지역 재료 | D9: 14 | E9: =D9/SUM($D$2:$D$13) -> 0.10218978 | F9: 1개
A10: 크레이터 평원 | B10: 충돌 유리 | C10: 지역 재료 | D10: 10 | E10: =D10/SUM($D$2:$D$13) -> 0.072992701 | F10: 1개
A11: 크레이터 평원 | B11: 레골리스 모래 | C11: 지역 재료 | D11: 5 | E11: =D11/SUM($D$2:$D$13) -> 0.03649635 | F11: 1개
A12: 크레이터 평원 | B12: 먼지감자 씨앗 | C12: 씨앗 | D12: 4 | E12: =D12/SUM($D$2:$D$13) -> 0.02919708 | F12: 1개
A13: 크레이터 평원 | B13: 운석무 씨앗 | C13: 씨앗 | D13: 4 | E13: =D13/SUM($D$2:$D$13) -> 0.02919708 | F13: 1개
A14: 크레이터 평원 합계 | D14: =SUM(D2:D13) -> 137 | E14: =SUM(E2:E13) -> 1
A16: 결정 동굴 | B16: 은하 결정 | C16: 기본 재료 | D16: 42 | E16: =D16/SUM($D$16:$D$24) -> 0.30656934 | F16: 1개
A17: 결정 동굴 | B17: 운석 파편 | C17: 기본 재료 | D17: 35 | E17: =D17/SUM($D$16:$D$24) -> 0.25547445 | F17: 1~2개
A18: 결정 동굴 | B18: 암흑물질 조각 | C18: 기본 재료 | D18: 12 | E18: =D18/SUM($D$16:$D$24) -> 0.087591241 | F18: 1개
A19: 결정 동굴 | B19: 성운 이끼 | C19: 기본 재료 | D19: 11 | E19: =D19/SUM($D$16:$D$24) -> 0.080291971 | F19: 1~2개
A20: 결정 동굴 | B20: 발광 석순 | C20: 지역 재료 | D20: 14 | E20: =D20/SUM($D$16:$D$24) -> 0.10218978 | F20: 1개
A21: 결정 동굴 | B21: 동굴 이끼버섯 | C21: 지역 재료 | D21: 10 | E21: =D21/SUM($D$16:$D$24) -> 0.072992701 | F21: 1개
A22: 결정 동굴 | B22: 공명 수정 | C22: 지역 재료 | D22: 5 | E22: =D22/SUM($D$16:$D$24) -> 0.03649635 | F22: 1개
A23: 결정 동굴 | B23: 수정 덩굴콩 씨앗 | C23: 씨앗 | D23: 4 | E23: =D23/SUM($D$16:$D$24) -> 0.02919708 | F23: 1개
A24: 결정 동굴 | B24: 그늘 버섯 씨앗 | C24: 씨앗 | D24: 4 | E24: =D24/SUM($D$16:$D$24) -> 0.02919708 | F24: 1개
A25: 결정 동굴 합계 | D25: =SUM(D16:D24) -> 137 | E25: =SUM(E16:E24) -> 1
A27: 이끼 습지 | B27: 성운 이끼 | C27: 기본 재료 | D27: 45 | E27: =D27/SUM($D$27:$D$36) -> 0.32846715 | F27: 1~2개
A28: 이끼 습지 | B28: 별감자 씨앗 | C28: 씨앗 | D28: 18 | E28: =D28/SUM($D$27:$D$36) -> 0.13138686 | F28: 1개
A29: 이끼 습지 | B29: 네온베리 씨앗 | C29: 씨앗 | D29: 16 | E29: =D29/SUM($D$27:$D$36) -> 0.11678832 | F29: 1개
A30: 이끼 습지 | B30: 월광호박 씨앗 | C30: 씨앗 | D30: 8 | E30: =D30/SUM($D$27:$D$36) -> 0.058394161 | F30: 1개
A31: 이끼 습지 | B31: 은하 결정 | C31: 기본 재료 | D31: 13 | E31: =D31/SUM($D$27:$D$36) -> 0.094890511 | F31: 1개
A32: 이끼 습지 | B32: 메탄 진흙 | C32: 지역 재료 | D32: 14 | E32: =D32/SUM($D$27:$D$36) -> 0.10218978 | F32: 1개
A33: 이끼 습지 | B33: 늪 갈대 | C33: 지역 재료 | D33: 10 | E33: =D33/SUM($D$27:$D$36) -> 0.072992701 | F33: 1개
A34: 이끼 습지 | B34: 고대 화석 | C34: 지역 재료 | D34: 5 | E34: =D34/SUM($D$27:$D$36) -> 0.03649635 | F34: 1개
A35: 이끼 습지 | B35: 안개 연꽃 씨앗 | C35: 씨앗 | D35: 4 | E35: =D35/SUM($D$27:$D$36) -> 0.02919708 | F35: 1개
A36: 이끼 습지 | B36: 늪 쌀 씨앗 | C36: 씨앗 | D36: 4 | E36: =D36/SUM($D$27:$D$36) -> 0.02919708 | F36: 1개
A37: 이끼 습지 합계 | D37: =SUM(D27:D36) -> 137 | E37: =SUM(E27:E36) -> 1
A39: 잔해 지대 | B39: 운석 파편 | C39: 기본 재료 | D39: 40 | E39: =D39/SUM($D$39:$D$48) -> 0.31007752 | F39: 1~2개
A40: 잔해 지대 | B40: 은하 결정 | C40: 기본 재료 | D40: 14 | E40: =D40/SUM($D$39:$D$48) -> 0.10852713 | F40: 1개
A41: 잔해 지대 | B41: 응급 수리 키트 | C41: 보급품 | D41: 5 | E41: =D41/SUM($D$39:$D$48) -> 0.03875969 | F41: 1개
A42: 잔해 지대 | B42: 월광호박 씨앗 | C42: 씨앗 | D42: 6 | E42: =D42/SUM($D$39:$D$48) -> 0.046511628 | F42: 1개
A43: 잔해 지대 | B43: 성운 이끼 | C43: 기본 재료 | D43: 27 | E43: =D43/SUM($D$39:$D$48) -> 0.20930233 | F43: 1~2개
...

Sheet 규칙
A1: 채집 규칙과 입력값
A2: 노란 칸(파란 글씨)을 바꾸면 「기대 수량」 시트가 다시 계산됩니다. 수치는 게임 코드(index.html의 SITES·claimGather)에서 그대로 옮겼습니다.
A4: 항목 | B4: 값 | C4: 설명
A5: 항해사 직업인가요? (1=예, 0=아니오) | B5: 0 | C5: 항해사는 채집 1회마다 50% 확률로 한 번 더 뽑습니다.
A6: 채집 숙련 레벨 (0~30) | B6: 0 | C6: 숙련 레벨 × 0.5% 확률로 한 번 더 뽑습니다. (황금 손 칭호 보너스는 제외)
A7: 기본 뽑기 횟수 (채집 1회당, 1~2회 평균) | B7: 1.5 | C7: 코드: ri(1,2) → 1회 또는 2회가 같은 확률
A8: 운석 파편·성운 이끼 개수 (1~2개 평균) | B8: 1.5 | C8: 이 두 아이템만 한 번 뽑힐 때 1~2개, 나머지는 1개
A9: 고대 신호 기록 확률 (채집 1회당) | B9: 0.03 | C9: 레벨에 맞는 등급 1개 (Lv1~9 6급 … Lv50+ 1급)
A10: 희귀 무기 확률 (채집 1회당) | B10: 0.03 | C10: 한 번 받기에 최대 1개, 아직 없는 무기 중에서
A12: 채집 1회당 평균 뽑기 횟수 | B12: =B7+B5*0.5+B6*0.005 -> 1.5 | C12: 기본 1.5 + 항해사 0.5 + 숙련 보너스
A14: 채집 시간별 채집 횟수
A15: 보내는 시간 | B15: 채집 횟수
A16: 10분 | B16: 1
A17: 30분 | B17: 2
A18: 1시간 | B18: 3
A19: 2시간 | B19: 7
A20: 4시간 | B20: 12
A21: 8시간 | B21: 20
A22: 12시간 | B22: 28

Sheet 기대 수량
A1: 채집 1회 / 시간별 평균 기대 수량
A2: 보낼 시간의 채집 횟수 → | B2: 7 | C2: (「규칙」 시트의 시간별 횟수 중 하나를 넣으십시오. 기본 7 = 2시간)
A4: 장소 | B4: 아이템 | C4: 한 번 뽑을 때 확률 | D4: 채집 1회당 기대 개수 | E4: 위 횟수만큼 보냈을 때 기대 개수
A5: 크레이터 평원 | B5: 운석 파편 | C5: ='채집 확률표'!E2 -> 0.2919708 | D5: =C5*규칙!$B$12*규칙!$B$8 -> 0.65693431 | E5: =D5*$B$2 -> 4.5985401
A6: 크레이터 평원 | B6: 성운 이끼 | C6: ='채집 확률표'!E3 -> 0.1459854 | D6: =C6*규칙!$B$12*규칙!$B$8 -> 0.32846715 | E6: =D6*$B$2 -> 2.2992701
A7: 크레이터 평원 | B7: 은하 결정 | C7: ='채집 확률표'!E4 -> 0.10948905 | D7: =C7*규칙!$B$12*1 -> 0.16423358 | E7: =D7*$B$2 -> 1.149635
A8: 크레이터 평원 | B8: 별감자 씨앗 | C8: ='채집 확률표'!E5 -> 0.072992701 | D8: =C8*규칙!$B$12*1 -> 0.10948905 | E8: =D8*$B$2 -> 0.76642336
A9: 크레이터 평원 | B9: 네온베리 씨앗 | C9: ='채집 확률표'!E6 -> 0.058394161 | D9: =C9*규칙!$B$12*1 -> 0.087591241 | E9: =D9*$B$2 -> 0.61313869
A10: 크레이터 평원 | B10: 월광호박 씨앗 | C10: ='채집 확률표'!E7 -> 0.02189781 | D10: =C10*규칙!$B$12*1 -> 0.032846715 | E10: =D10*$B$2 -> 0.22992701
A11: 크레이터 평원 | B11: 암흑물질 조각 | C11: ='채집 확률표'!E8 -> 0.02919708 | D11: =C11*규칙!$B$12*1 -> 0.04379562 | E11: =D11*$B$2 -> 0.30656934
A12: 크레이터 평원 | B12: 철운석 덩어리 | C12: ='채집 확률표'!E9 -> 0.10218978 | D12: =C12*규칙!$B$12*1 -> 0.15328467 | E12: =D12*$B$2 -> 1.0729927
A13: 크레이터 평원 | B13: 충돌 유리 | C13: ='채집 확률표'!E10 -> 0.072992701 | D13: =C13*규칙!$B$12*1 -> 0.10948905 | E13: =D13*$B$2 -> 0.76642336
A14: 크레이터 평원 | B14: 레골리스 모래 | C14: ='채집 확률표'!E11 -> 0.03649635 | D14: =C14*규칙!$B$12*1 -> 0.054744526 | E14: =D14*$B$2 -> 0.38321168
A15: 크레이터 평원 | B15: 먼지감자 씨앗 | C15: ='채집 확률표'!E12 -> 0.02919708 | D15: =C15*규칙!$B$12*1 -> 0.04379562 | E15: =D15*$B$2 -> 0.30656934
A16: 크레이터 평원 | B16: 운석무 씨앗 | C16: ='채집 확률표'!E13 -> 0.02919708 | D16: =C16*규칙!$B$12*1 -> 0.04379562 | E16: =D16*$B$2 -> 0.30656934
A18: 결정 동굴 | B18: 은하 결정 | C18: ='채집 확률표'!E16 -> 0.30656934 | D18: =C18*규칙!$B$12*1 -> 0.45985401 | E18: =D18*$B$2 -> 3.2189781
A19: 결정 동굴 | B19: 운석 파편 | C19: ='채집 확률표'!E17 -> 0.25547445 | D19: =C19*규칙!$B$12*규칙!$B$8 -> 0.57481752 | E19: =D19*$B$2 -> 4.0237226
A20: 결정 동굴 | B20: 암흑물질 조각 | C20: ='채집 확률표'!E18 -> 0.087591241 | D20: =C20*규칙!$B$12*1 -> 0.13138686 | E20: =D20*$B$2 -> 0.91970803
A21: 결정 동굴 | B21: 성운 이끼 | C21: ='채집 확률표'!E19 -> 0.080291971 | D21: =C21*규칙!$B$12*규칙!$B$8 -> 0.18065693 | E21: =D21*$B$2 -> 1.2645985
A22: 결정 동굴 | B22: 발광 석순 | C22: ='채집 확률표'!E20 -> 0.10218978 | D22: =C22*규칙!$B$12*1 -> 0.15328467 | E22: =D22*$B$2 -> 1.0729927
A23: 결정 동굴 | B23: 동굴 이끼버섯 | C23: ='채집 확률표'!E21 -> 0.072992701 | D23: =C23*규칙!$B$12*1 -> 0.10948905 | E23: =D23*$B$2 -> 0.76642336
A24: 결정 동굴 | B24: 공명 수정 | C24: ='채집 확률표'!E22 -> 0.03649635 | D24: =C24*규칙!$B$12*1 -> 0.054744526 | E24: =D24*$B$2 -> 0.38321168
A25: 결정 동굴 | B25: 수정 덩굴콩 씨앗 | C25: ='채집 확률표'!E23 -> 0.02919708 | D25: =C25*규칙!$B$12*1 -> 0.04379562 | E25: =D25*$B$2 -> 0.30656934
A26: 결정 동굴 | B26: 그늘 버섯 씨앗 | C26: ='채집 확률표'!E24 -> 0.02919708 | D26: =C26*규칙!$B$12*1 -> 0.04379562 | E26: =D26*$B$2 -> 0.30656934
A28: 이끼 습지 | B28: 성운 이끼 | C28: ='채집 확률표'!E27 -> 0.32846715 | D28: =C28*규칙!$B$12*규칙!$B$8 -> 0.73905109 | E28: =D28*$B$2 -> 5.1733577
A29: 이끼 습지 | B29: 별감자 씨앗 | C29: ='채집 확률표'!E28 -> 0.13138686 | D29: =C29*규칙!$B$12*1 -> 0.19708029 | E29: =D29*$B$2 -> 1.379562
A30: 이끼 습지 | B30: 네온베리 씨앗 | C30: ='채집 확률표'!E29 -> 0.11678832 | D30: =C30*규칙!$B$12*1 -> 0.17518248 | E30: =D30*$B$2 -> 1.2262774
A31: 이끼 습지 | B31: 월광호박 씨앗 | C31: ='채집 확률표'!E30 -> 0.058394161 | D31: =C31*규칙!$B$12*1 -> 0.087591241 | E31: =D31*$B$2 -> 0.61313869
A32: 이끼 습지 | B32: 은하 결정 | C32: ='채집 확률표'!E31 -> 0.094890511 | D32: =C32*규칙!$B$12*1 -> 0.14233577 | E32: =D32*$B$2 -> 0.99635036
A33: 이끼 습지 | B33: 메탄 진흙 | C33: ='채집 확률표'!E32 -> 0.10218978 | D33: =C33*규칙!$B$12*1 -> 0.15328467 | E33: =D33*$B$2 -> 1.0729927
A34: 이끼 습지 | B34: 늪 갈대 | C34: ='채집 확률표'!E33 -> 0.072992701 | D34: =C34*규칙!$B$12*1 -> 0.10948905 | E34: =D34*$B$2 -> 0.76642336
A35: 이끼 습지 | B35: 고대 화석 | C35: ='채집 확률표'!E34 -> 0.03649635 | D35: =C35*규칙!$B$12*1 -> 0.054744526 | E35: =D35*$B$2 -> 0.38321168
A36: 이끼 습지 | B36: 안개 연꽃 씨앗 | C36: ='채집 확률표'!E35 -> 0.02919708 | D36: =C36*규칙!$B$12*1 -> 0.04379562 | E36: =D36*$B$2 -> 0.30656934
A37: 이끼 습지 | B37: 늪 쌀 씨앗 | C37: ='채집 확률표'!E36 -> 0.02919708 | D37: =C37*규칙!$B$12*1 -> 0.04379562 | E37: =D37*$B$2 -> 0.30656934
A39: 잔해 지대 | B39: 운석 파편 | C39: ='채집 확률표'!E39 -> 0.31007752 | D39: =C39*규칙!$B$12*규칙!$B$8 -> 0.69767442 | E39: =D39*$B$2 -> 4.8837209
A40: 잔해 지대 | B40: 은하 결정 | C40: ='채집 확률표'!E40 -> 0.10852713 | D40: =C40*규칙!$B$12*1 -> 0.1627907 | E40: =D40*$B$2 -> 1.1395349
A41: 잔해 지대 | B41: 응급 수리 키트 | C41: ='채집 확률표'!E41 -> 0.03875969 | D41: =C41*규칙!$B$12*1 -> 0.058139535 | E41: =D41*$B$2 -> 0.40697674
A42: 잔해 지대 | B42: 월광호박 씨앗 | C42: ='채집 확률표'!E42 -> 0.046511628 | D42: =C42*규칙!$B$12*1 -> 0.069767442 | E42: =D42*$B$2 -> 0.48837209
A43: 잔해 지대 | B43: 성운 이끼 | C43: ='채집 확률표'!E43 -> 0.20930233 | D43: =C43*규칙!$B$12*규칙!$B$8 -> 0.47093023 | E43: =D43*$B$2 -> 3.2965116
A44: 잔해 지대 | B44: 낡은 회로판 | C44: ='채집 확률표'!E44 -> 0.10852713 | D44: =C44*규칙!$B$12*1 -> 0.1627907 | E44: =D44*$B$2 -> 1.1395349
...
